Workbook

Sheet Legend
A1: Dream-Drive MS — functionality tracker
A2: Greenfield rebuild at dream-drive-MS (NestJS API :4000 + Next.js web/admin + Expo). Live product still in client-main/backend. Snapshot date: 2026-08-31.
A4: How to read status
A5: Status | B5: Meaning
A6: Done | B6: Coded and usable (API + persistence). May still need production keys or UI polish.
A7: In Progress | B7: Partial: endpoint or screen exists but validations, UI, or edge cases are incomplete.
A8: Under Review | B8: Implemented with mock/fallback (Razorpay, Leegality, Gmail, Firebase). Needs staging verification.
A9: Not Started | B9: Not built in this repo yet (or explicitly out of scope).
A11: Out of scope (confirmed)
A12: Delivery / pickup executive operations
A13: Partner self-service portal (admin manages partners)
A15: Stack
A16: Next.js 15 web :3000 (ported marketing site + new /fleet checkout path) · Next.js admin :3001 · NestJS API :4000 (identity, catalog, booking, payment, document, fleet, partner, notify, platform) · worker HOLD sweeper · socket :4010 · PostgreSQL/Prisma · Firebase Auth · Razorpay · Leegality · Zoho Forms · Expo mobile.
A18: How to refresh this Google Sheet
A19: File → Import → Upload Dream-Drive-Functionality-Tracker.xlsx → Import location: Replace spreadsheet. Each module is its own tab. Change Status via the dropdown; colours follow the cell.
A21: Frontend developer tabs
A22: FE Web Public, FE Web Account, FE Admin, FE Mobile — one row per page: route, how it should function, what exists today, APIs, status. Same dropdown: Done / In Progress / Under Review / Not Started.

Sheet FE Web Account
A1: Frontend — customer dashboard (apps/web)
A2: Service: apps/web :3000 | Priority: P0 | Overall status: In Progress
A3: Logged-in area. Guard all /account/* with AuthContext; redirect to /login. Customer can only see own data. Support must not impersonate. Nine pages are listed starting at row 5 (scroll to the top of this tab).
A4: ID | B4: Page | C4: Route | D4: How it should function | E4: What exists today + APIs | F4: Status | G4: Priority | H4: Gaps / next work
A5: FE.A.01 | B5: Account home | C5: /account | D5: Greeting, KYC status chip, shortcuts (bookings, KYC, invoices, tickets). Latest 5 bookings with status and track link. Edit name/phone. | E5: Account.jsx shows name, KYC, booking list, KYC link, sign out. GET /v1/me/bookings. | F5: In Progress | G5: P0 | H5: Profile edit form (PATCH /v1/me); nav to invoices/wallet/tickets.
A6: FE.A.02 | B6: My bookings | C6: /account/bookings | D6: Table/cards of all bookings: publicId, car, dates, amount, status. Filter by status. Click → detail or /track/:id. | E6: List is inline on /account only. No dedicated route. | F6: In Progress | G6: P0 | H6: Add /account/bookings page; empty state; cancel CTA with confirm.
A7: FE.A.03 | B7: Booking detail | C7: /account/bookings/:id | D7: Full timeline, vehicle/driver once assigned, pay remaining balance + deposit, links to KYC, agreement, invoices. Cancel until handover. | E7: Uses /track/:bookingId. GET /v1/bookings/:id returns history, payments, KYC, agreements, driver, inspections. | F7: In Progress | G7: P0 | H7: Pay balance/deposit buttons; cancel; download invoice.
A8: FE.A.04 | B8: KYC upload | C8: /account/kyc | D8: Upload Aadhaar, PAN, DL, selfie (pdf/jpg/png). Show status NOT_STARTED → SUBMITTED → APPROVED/REJECTED. Rejection reason + re-upload. After approve, prompt to sign agreement. | E8: Kyc.jsx exists. POST /v1/kyc/submit, GET /v1/me/kyc. Uploads currently send a URL (no signed Cloudinary slot UI). | F8: In Progress | G8: P0 | H8: Per-doc pickers; Cloudinary signed upload; rejection UX.
A9: FE.A.05 | B9: Agreements | C9: /account/agreements | D9: List agreements per booking. Open Leegality sign link. Download signed PDF when ready. Status DRAFT/SENT/SIGNED. | E9: No page. GET /v1/me/agreements/:id is by id only (no list). | F9: Not Started | G9: P0 | H9: Needs list endpoint or derive from booking.agreements; then build UI.
A10: FE.A.06 | B10: Invoices | C10: /account/invoices | D10: List tax invoices (number, date, amount, GST). Download/print. Link to booking. | E10: No page. GET /v1/me/invoices returns Invoice + lines. No PDF yet. | F10: Not Started | G10: P0 | H10: Build list + print view even if PDF comes later.
A11: FE.A.07 | B11: Wallet | C11: /account/wallet | D11: Show balance (INR) and last 50 txns. Later: pay part of token from wallet. | E11: No page. GET /v1/me/wallet exists (balance 0, no debit at checkout). | F11: Not Started | G11: P2 | H11: Read-only UI is enough until wallet pay is built.
A12: FE.A.08 | B12: Support tickets | C12: /account/tickets | D12: Open a ticket (subject, body, optional booking). List status. Reply thread. Cannot see internal notes. | E12: No page. POST /v1/tickets exists. No customer list/reply UI. | F12: Not Started | G12: P2 | H12: Add list + thread when GET /v1/me/tickets exists (today only POST).
A13: FE.A.09 | B13: Addresses / profile | C13: /account (section) or /account/profile | D13: Edit full name, phone (re-OTP later), default city, addresses. Once KYC approved, name matches KYC unless admin override. | E13: PATCH /v1/me accepts fullName, phone, address JSON. No form. | F13: Not Started | G13: P0 | H13: Simple profile form on account home is enough for MVP.
A15: Counts | B15: Done | C15: In Progress | D15: Under Review | E15: Not Started
B16: =COUNTIF(F5:F13,"Done") | C16: =COUNTIF(F5:F13,"In Progress") | D16: =COUNTIF(F5:F13,"Under Review") | E16: =COUNTIF(F5:F13,"Not Started")

Sheet FE Web Public
A1: Frontend — public website (apps/web)
A2: Service: apps/web :3000 | Priority: P0–P1 | Overall status: In Progress
A3: Customer-facing marketing + booking path. New MS pages live under /fleet, /login, /checkout, /account, /track. Ported CRA pages still cover home, blogs, contact. Frontend owns UI, forms, Razorpay checkout widget, and calling NEXT_PUBLIC_API_URL (port 4000). No Prisma/Firebase Admin in the browser.
A4: ID | B4: Page | C4: Route | D4: How it should function | E4: What exists today + APIs | F4: Status | G4: Priority | H4: Gaps / next work
A5: FE.W.01 | B5: Home | C5: / | D5: Hero with city + dates search CTA that goes to /fleet. Show CMS banners, featured cars, how-it-works, testimonials, blogs teaser, WhatsApp/enquiry CTAs. Promo strips (sale/monsoon) come from GET /v1/public/banners, not hardcoded CSS. | E5: Ported Home.jsx + Hero + MonsoonPromoBar (hardcoded). Does not call banners API. | F5: In Progress | G5: P1 | H5: Wire banners/CMS; search form should land on /fleet with query params.
A6: FE.W.02 | B6: Fleet / search | C6: /fleet (also /cars) | D6: Filters: city, from/to, rental type (self-drive vs chauffeur), seats, fuel, transmission, price. Results show image, from-price, available flag. Unavailable cars greyed. Sort by price. Clicking a card opens car detail with the same dates. | E6: Search.jsx on /fleet calls GET /v1/public/cities + /v1/public/search (city/dates/SELF_DRIVE only). /cars is still the old FleetCarousel. | F6: In Progress | G6: P0 | H6: Add remaining filters; unify /cars vs /fleet; pass dates into detail.
A7: FE.W.03 | B7: Car detail + quote | C7: /cars/:slug | D7: Gallery, specs, city, from-price. Date/time + rental-type picker. Show blocked dates / availability. CTA creates a quote then navigates to /checkout/:quoteId. Guest can browse; checkout requires login. | E7: CarDetail.jsx exists. GET /v1/public/cars/:slug and availability. Calendar of blocked dates is thin. | F7: In Progress | G7: P0 | H7: POST /v1/quotes from this page; blocked-date calendar; pickup/drop branch.
A8: FE.W.04 | B8: Login | C8: /login | D8: Email/password (Firebase) and email OTP. On success: POST /v1/auth/sync, store Bearer token, redirect to /account or intended checkout URL. Show errors and OTP resend cooldown. | E8: Login.jsx is a local demo: loginDev(email) only. AuthContext.jsx holds the token. | F8: In Progress | G8: P0 | H8: Real Firebase Auth + OTP send/verify UI. Google social login later.
A9: FE.W.05 | B9: Checkout (quote review) | C9: /checkout/:quoteId | D9: Show frozen price, dates, car, deposit, offer-code field. Confirm creates booking (HOLD) then starts token payment. If quote expired, send back to car detail. Login gate if anonymous. | E9: Checkout.jsx applies offer, POST /v1/bookings, POST /v1/payments/orders, mock-verifies, then success. No quote GET (uses id from URL only). | F9: In Progress | G9: P0 | H9: Load quote details; login redirect; do not mock-verify when Razorpay keys exist.
A10: FE.W.06 | B10: Pay (Razorpay) | C10: /checkout/pay | D10: Open Razorpay Checkout with orderId, keyId, amount from POST /v1/payments/orders. On success call POST /v1/payments/verify, then poll GET /v1/payments/:id until SUCCESS (webhook is source of truth). Handle failure/cancel. | E10: No /checkout/pay route. Checkout.jsx verifies immediately when order.mock is true. | F10: Not Started | G10: P0 | H10: Add Razorpay.js checkout page; poll payment status; never trust client success alone.
A11: FE.W.07 | B11: Booking success | C11: /checkout/success | D11: Show public booking id, amount, next steps: KYC (self-drive) or wait for confirm (with-driver). Links to /account/kyc and /track/:id. | E11: SuccessMs.jsx exists after mock pay. | F11: In Progress | G11: P0 | H11: Poll payment; branch copy for self-drive vs chauffeur.
A12: FE.W.08 | B12: Track booking | C12: /track/:bookingId | D12: Timeline: HOLD → payment → KYC → signature → confirmed → handover → ongoing → return → completed. Logged-in users use GET /v1/bookings/:id. Logged-out: id + phone OTP (later). Show driver name after assignment. | E12: Track.jsx on /track/:bookingId. Old /order-tracking still exists. Guest OTP not built. | F12: In Progress | G12: P0 | H12: Guest track; live status via socket :4010 optional.
A13: FE.W.09 | B13: Blogs | C13: /blogs /blogs/:slug | D13: List published posts with hero image, date, category. Detail shows body + comments (if enabled). SEO title/description from CMS. | E13: AllBlogs / Blogspage ported (old context/Firestore). API GET /v1/public/blogs and /:slug exists. | F13: In Progress | G13: P1 | H13: Point UI at platform API; drop Firestore blog context.
A14: FE.W.10 | B14: Contact / enquiry | C14: /contact | D14: Name, phone or email, city, message. Submit POST /v1/public/contact (creates CRM lead). Success toast. WhatsApp CTA can fire POST /v1/public/leads with source=whatsapp. | E14: Ported Contact.jsx + WhatsAppPopup. May still hit old backend. | F14: In Progress | G14: P1 | H14: Switch to API; track WhatsApp clicks as leads.
A15: FE.W.11 | B15: CMS / legal pages | C15: /about /howitworks /termsandconditions /legal/:slug | D15: Render published CmsPage by slug (title + body + meta). Admin can update without a deploy. | E15: Static About, HowItWorks, TermsAndConditions components. GET /v1/public/pages/:slug exists unused. | F15: In Progress | G15: P1 | H15: Drive these from CMS; add /legal/:slug.
... A18: FE.W.14 | B18: Testimonials | C18: /testimonials (and home module) | D18: Published testimonials on home. Optional listing page. | E18: Testimonial.jsx + TestimonialContext (old). No new API. | F18: Not Started | G18: P1 | H18: Needs public testimonials API first, then wire home.
A20: Counts | B20: Done | C20: In Progress | D20: Under Review | E20: Not Started
B21: =COUNTIF(F5:F18,"Done") | C21: =COUNTIF(F5:F18,"In Progress") | D21: =COUNTIF(F5:F18,"Under Review") | E21: =COUNTIF(F5:F18,"Not Started")

Sheet FE Admin
A1: Frontend — operations console (apps/admin :3001)
A2: Service: apps/admin | Priority: P0–P1 | Overall status: In Progress
A3: Staff-only Next.js app. Token in localStorage (dd_token). Sidebar Shell. Role-aware nav later (SUPER_ADMIN sees all). Call the same API :4000. Old Firestore admin still lives under apps/web /admin — do not extend it; migrate screens here.
A4: ID | B4: Page | C4: Route | D4: How it should function | E4: What exists today + APIs | F4: Status | G4: Priority | H4: Gaps / next work
A5: FE.AD.01 | B5: Admin login | C5: /login | D5: Staff email login (Firebase or dev token). Reject CUSTOMER role. Redirect to dashboard. | E5: apps/admin/app/login/page.jsx exists. | F5: In Progress | G5: P0 | H5: Block non-staff; show role; production Firebase.
A6: FE.AD.02 | B6: Dashboard | C6: / | D6: KPI cards: bookings, pending KYC, pending signatures, failed payments, today’s handovers, overdue returns, vehicles in workshop, revenue. Filter city + date. Status breakdown table. | E6: app/page.jsx shows bookings, pending KYC, vehicles free, revenue, byStatus. GET /v1/admin/dashboard. | F6: In Progress | G6: P1 | H6: Add remaining KPIs when API returns them; city filter.
A7: FE.AD.03 | B7: Bookings list | C7: /bookings | D7: Filter by status, city, dates, q. Columns: publicId, customer, car, dates, amount, status. Row click → detail. | E7: app/bookings/page.jsx exists (list). | F7: In Progress | G7: P0 | H7: Filters + pagination; status chips.
A8: FE.AD.04 | B8: Booking detail + ops | C8: /bookings/[id] | D8: Timeline, notes, flight number. Actions: change status, assign vehicle, assign driver, handover (odometer, fuel, photos), return (+ damages), generate/send agreement, mark signed, record offline pay. Show payments/KYC/inspections. | E8: No [id] page. APIs: GET booking, PATCH, POST status/assign-vehicle/assign-driver, POST handover/return, agreements, offline pay. | F8: Not Started | G8: P0 | H8: Highest-value admin screen after list. Build this next.
A9: FE.AD.05 | B9: Car models | C9: /cars | D9: CRUD models: name, slug, type, seats, fuel, transmission, city, published, featured, images, pricing rules (daily/hourly/deposit). | E9: app/cars/page.jsx + GET/POST/PATCH /v1/admin/car-models and pricing-rules. | F9: In Progress | G9: P0 | H9: Image manager; inline pricing editor.
A10: FE.AD.06 | B10: Vehicles | C10: /vehicles | D10: CRUD physical cars: registration, model, branch, status, odometer, partner. Expiry alerts for RC/insurance/PUC. | E10: app/vehicles/page.jsx + /v1/admin/vehicles. GET expiries exists, no document CRUD UI. | F10: In Progress | G10: P0 | H10: Status change; branch transfer; document expiry panel.
A11: FE.AD.07 | B11: Availability calendar | C11: /availability | D11: Per city/branch, see vehicles blocked by bookings, HOLD, maintenance. Staff can add a manual block. | E11: No page. Availability is computed in catalog search. | F11: Not Started | G11: P1 | H11: Read-only calendar first; manual block later.
A12: FE.AD.08 | B12: Customers | C12: /customers | D12: Search users. View profile, roles, bookings. SUPER_ADMIN: set roles, disable. No impersonation. | E12: app/customers/page.jsx + GET /v1/admin/users, PATCH roles, POST disable. | F12: In Progress | G12: P0 | H12: Customer drawer with bookings + KYC; role editor.
A13: FE.AD.09 | B13: KYC queue | C13: /kyc | D13: Queue SUBMITTED/UNDER_REVIEW. Open docs. Approve/reject with notes. Decision advances self-drive booking. | E13: app/kyc/page.jsx + GET /v1/admin/kyc, POST .../decision. | F13: In Progress | G13: P0 | H13: Doc viewer; reject reason required.
A14: FE.AD.10 | B14: Agreements | C14: /agreements | D14: List envelopes. Generate PDF, send Leegality, mark signed (waiver), void/re-issue later. | E14: No admin page. APIs: generate, send-leegality, mark-signed. | F14: Not Started | G14: P0 | H14: Can also live as actions on booking detail for MVP.
A15: FE.AD.11 | B15: Payments / invoices / deposits | C15: /payments /invoices /deposits | D15: List payments. Record offline cash/UPI. Refund (finance). Capture/release deposit. Show invoice numbers. | E15: app/payments/page.jsx only. Refund/deposit/offline APIs exist without dedicated UI. | F15: In Progress | G15: P0 | H15: Add refund + offline + deposit actions; invoices tab.
... A26: FE.AD.22 | B26: Notification log + templates | C26: /notifications | D26: Delivery log. Edit email templates by key. Resend later. | E26: No page. GET logs + PUT templates exist. | F26: Not Started | G26: P1 | H26: Simple table + template editor.
A28: Counts | B28: Done | C28: In Progress | D28: Under Review | E28: Not Started
B29: =COUNTIF(F5:F26,"Done") | C29: =COUNTIF(F5:F26,"In Progress") | D29: =COUNTIF(F5:F26,"Under Review") | E29: =COUNTIF(F5:F26,"Not Started")

Sheet FE Mobile
A1: Frontend — customer Expo app (apps/mobile)
A2: Service: apps/mobile | Priority: P2 | Overall status: In Progress
A3: Same /v1 APIs as web. Do not build full navigation until web checkout + KYC + pay work. Current App.tsx is a single-screen prototype.
A4: ID | B4: Page | C4: Route | D4: How it should function | E4: What exists today + APIs | F4: Status | G4: Priority | H4: Gaps / next work
A5: FE.M.01 | B5: Splash / force-update | C5: screen 1 | D5: Brand splash. If app version < min, block with store link. | E5: Not built. | F5: Not Started | G5: P2 | H5: Needs min-version from API or remote config.
A6: FE.M.02 | B6: Login / OTP | C6: screen 2 | D6: Email OTP or Firebase phone/email. Store token. POST /v1/auth/sync. POST /v1/me/devices for FCM. | E6: Dev token only (Bearer dev:email) on App.tsx. | F6: Not Started | G6: P2 | H6: No OTP UI.
A7: FE.M.03 | B7: Home + search | C7: screens 3–4 | D7: City + dates + type. Results from GET /v1/public/search. | E7: App.tsx lists cars from search on load, no filters. | F7: In Progress | G7: P2 | H7: Filters, pull-to-refresh, empty state.
A8: FE.M.04 | B8: Car detail | C8: screen 5 | D8: Gallery, availability calendar, quote CTA. | E8: Not built (name + price only on list). | F8: Not Started | G8: P2
A9: FE.M.05 | B9: Checkout + Razorpay | C9: screens 6–7 | D9: Quote → booking → Razorpay native checkout → verify/poll. | E9: Not built. | F9: Not Started | G9: P2 | H9: After web Razorpay path is proven.
A10: FE.M.06 | B10: KYC + agreement | C10: screen 8 | D10: Upload docs (camera/gallery). Open Leegality in-app browser. | E10: Not built. | F10: Not Started | G10: P2
A11: FE.M.07 | B11: Bookings + tracking | C11: screens 9–10 | D11: List + timeline. Deep link dreamdrive://bookings/:id. | E11: App.tsx shows publicId + status after dev login. | F11: In Progress | G11: P2 | H11: Detail timeline; push open.
A12: FE.M.08 | B12: Profile, tickets, notifications | C12: screens 11–13 | D12: Profile, support ticket, in-app notification list. | E12: Not built. | F12: Not Started | G12: P2
A14: Counts | B14: Done | C14: In Progress | D14: Under Review | E14: Not Started
B15: =COUNTIF(F5:F12,"Done") | C15: =COUNTIF(F5:F12,"In Progress") | D15: =COUNTIF(F5:F12,"Under Review") | E15: =COUNTIF(F5:F12,"Not Started")

Sheet 00 Summary
A1: Dream-Drive MS — module + frontend summary
A2: Change Status on each module tab. Counts below use COUNTIF against that tab. Overall status is the current engineering judgement for the module as a whole.
A4: # | B4: Module | C4: Service | D4: Priority | E4: Overall status | F4: Done | G4: In Progress | H4: Under Review | I4: Not Started | J4: Total items | K4: % Done | L4: Notes
A5: 1 | B5: FE Web Account | C5: apps/web :3000 | D5: P0 | E5: In Progress | F5: =COUNTIF('FE Web Account'!F:F,"Done") | G5: =COUNTIF('FE Web Account'!F:F,"In Progress") | H5: =COUNTIF('FE Web Account'!F:F,"Under Review") | I5: =COUNTIF('FE Web Account'!F:F,"Not Started") | J5: =F5+G5+H5+I5 | K5: =IF(J5=0,0,F5/J5) | L5: Logged-in area. Guard all /account/* with AuthContext; redirect to /login. Customer can only see own data. Support must not impersonate. Nine pages are listed starting at row 5 (scroll to the top of this tab).
A6: 2 | B6: FE Web Public | C6: apps/web :3000 | D6: P0–P1 | E6: In Progress | F6: =COUNTIF('FE Web Public'!F:F,"Done") | G6: =COUNTIF('FE Web Public'!F:F,"In Progress") | H6: =COUNTIF('FE Web Public'!F:F,"Under Review") | I6: =COUNTIF('FE Web Public'!F:F,"Not Started") | J6: =F6+G6+H6+I6 | K6: =IF(J6=0,0,F6/J6) | L6: Customer-facing marketing + booking path. New MS pages live under /fleet, /login, /checkout, /account, /track. Ported CRA pages still cover home, blogs, contact. Frontend owns UI, forms, Razorpay checkout widget, and calling NEXT_PUBLIC_API_URL (port 4000). No Prisma/Firebase Admin in the browser.
A7: 3 | B7: FE Admin | C7: apps/admin | D7: P0–P1 | E7: In Progress | F7: =COUNTIF('FE Admin'!F:F,"Done") | G7: =COUNTIF('FE Admin'!F:F,"In Progress") | H7: =COUNTIF('FE Admin'!F:F,"Under Review") | I7: =COUNTIF('FE Admin'!F:F,"Not Started") | J7: =F7+G7+H7+I7 | K7: =IF(J7=0,0,F7/J7) | L7: Staff-only Next.js app. Token in localStorage (dd_token). Sidebar Shell. Role-aware nav later (SUPER_ADMIN sees all). Call the same API :4000. Old Firestore admin still lives under apps/web /admin — do not extend it; migrate screens here.
A8: 4 | B8: FE Mobile | C8: apps/mobile | D8: P2 | E8: In Progress | F8: =COUNTIF('FE Mobile'!F:F,"Done") | G8: =COUNTIF('FE Mobile'!F:F,"In Progress") | H8: =COUNTIF('FE Mobile'!F:F,"Under Review") | I8: =COUNTIF('FE Mobile'!F:F,"Not Started") | J8: =F8+G8+H8+I8 | K8: =IF(J8=0,0,F8/J8) | L8: Same /v1 APIs as web. Do not build full navigation until web checkout + KYC + pay work. Current App.tsx is a single-screen prototype.
A9: 5 | B9: 01 Auth & Security | C9: identity (apps/api) | D9: P0 | E9: In Progress | F9: =COUNTIF('01 Auth & Security'!F:F,"Done") | G9: =COUNTIF('01 Auth & Security'!F:F,"In Progress") | H9: =COUNTIF('01 Auth & Security'!F:F,"Under Review") | I9: =COUNTIF('01 Auth & Security'!F:F,"Not Started") | J9: =F9+G9+H9+I9 | K9: =IF(J9=0,0,F9/J9) | L9: Firebase + Postgres user sync, OTP, roles, and audit exist. OTP is in-memory (not Redis). Google login and last-super-admin lock are not built. Staff city/branch scope is stored but not fully enforced on every list.
A10: 6 | B10: 02 Public CMS | C10: platform + apps/web | D10: P1 | E10: In Progress | F10: =COUNTIF('02 Public CMS'!F:F,"Done") | G10: =COUNTIF('02 Public CMS'!F:F,"In Progress") | H10: =COUNTIF('02 Public CMS'!F:F,"Under Review") | I10: =COUNTIF('02 Public CMS'!F:F,"Not Started") | J10: =F10+G10+H10+I10 | K10: =IF(J10=0,0,F10/J10) | L10: Ported marketing site still runs in Next.js (home, blogs, monsoon bar). New CMS APIs exist for pages, banners, blogs, contact. Admin CMS page is a first version. Testimonials/comments still largely on the old UI.
A11: 7 | B11: 03 Customer Dashboard | C11: identity + booking + payment + document + web | D11: P0 | E11: In Progress | F11: =COUNTIF('03 Customer Dashboard'!F:F,"Done") | G11: =COUNTIF('03 Customer Dashboard'!F:F,"In Progress") | H11: =COUNTIF('03 Customer Dashboard'!F:F,"Under Review") | I11: =COUNTIF('03 Customer Dashboard'!F:F,"Not Started") | J11: =F11+G11+H11+I11 | K11: =IF(J11=0,0,F11/J11) | L11: Logged-in /account lists bookings and KYC status. APIs exist for invoices, wallet, tickets, agreements-by-id. Dedicated screens for invoices/wallet/tickets/agreements are not built yet.
A12: 8 | B12: 04 Search & Availability | C12: catalog | D12: P0 | E12: In Progress | F12: =COUNTIF('04 Search & Availability'!F:F,"Done") | G12: =COUNTIF('04 Search & Availability'!F:F,"In Progress") | H12: =COUNTIF('04 Search & Availability'!F:F,"Under Review") | I12: =COUNTIF('04 Search & Availability'!F:F,"Not Started") | J12: =F12+G12+H12+I12 | K12: =IF(J12=0,0,F12/J12) | L12: Public search, car detail, availability, pricing CRUD, HOLD reserve/release/confirm, and the worker HOLD sweeper are implemented. Search UI is /fleet. Seasonal pricing and a hard DB lock against double-book are still open.
A13: 9 | B13: 05 Booking Engine | C13: booking | D13: P0 | E13: In Progress | F13: =COUNTIF('05 Booking Engine'!F:F,"Done") | G13: =COUNTIF('05 Booking Engine'!F:F,"In Progress") | H13: =COUNTIF('05 Booking Engine'!F:F,"Under Review") | I13: =COUNTIF('05 Booking Engine'!F:F,"Not Started") | J13: =F13+G13+H13+I13 | K13: =IF(J13=0,0,F13/J13) | L13: Quote → HOLD → pay → KYC → signature → CONFIRMED path is coded, with admin assign vehicle/driver and cancel. Self-drive vs with-driver branch after payment. Chauffeur product rules, policy-based cancel, and admin-created bookings are incomplete.
A14: 10 | B14: 06 Payments | C14: payment | D14: P0 | E14: Under Review | F14: =COUNTIF('06 Payments'!F:F,"Done") | G14: =COUNTIF('06 Payments'!F:F,"In Progress") | H14: =COUNTIF('06 Payments'!F:F,"Under Review") | I14: =COUNTIF('06 Payments'!F:F,"Not Started") | J14: =F14+G14+H14+I14 | K14: =IF(J14=0,0,F14/J14) | L14: Razorpay order + verify + webhook + mock mode, invoices with flat 18% GST, offline pay, refund rows, deposit flags. Live Razorpay, real refunds, state-wise GST, and deposit authorize/capture need review in staging.
A15: 11 | B15: 07 Subscription | C15: booking + catalog | D15: P2 | E15: In Progress | F15: =COUNTIF('07 Subscription'!F:F,"Done") | G15: =COUNTIF('07 Subscription'!F:F,"In Progress") | H15: =COUNTIF('07 Subscription'!F:F,"Under Review") | I15: =COUNTIF('07 Subscription'!F:F,"Not Started") | J15: =F15+G15+H15+I15 | K15: =IF(J15=0,0,F15/J15) | L15: Data model + POST /v1/subscriptions creates a SUBSCRIPTION booking from a plan. No public plans API, swap, pause, or recurring invoices. After-MVP.
A16: 12 | B16: 08 Airport & Packages | C16: booking | D16: P1–P2 | E16: In Progress | F16: =COUNTIF('08 Airport & Packages'!F:F,"Done") | G16: =COUNTIF('08 Airport & Packages'!F:F,"In Progress") | H16: =COUNTIF('08 Airport & Packages'!F:F,"Under Review") | I16: =COUNTIF('08 Airport & Packages'!F:F,"Not Started") | J16: =F16+G16+H16+I16 | K16: =IF(J16=0,0,F16/J16) | L16: Tour packages and city-pair one-way rates have APIs. Quote accepts all RentalType values but pricing is still daily/hourly rules only — no terminal wait slabs, night charges, or driver allowance.
A17: 13 | B17: 09 KYC & Documents | C17: document | D17: P0 | E17: In Progress | F17: =COUNTIF('09 KYC & Documents'!F:F,"Done") | G17: =COUNTIF('09 KYC & Documents'!F:F,"In Progress") | H17: =COUNTIF('09 KYC & Documents'!F:F,"Under Review") | I17: =COUNTIF('09 KYC & Documents'!F:F,"Not Started") | J17: =F17+G17+H17+I17 | K17: =IF(J17=0,0,F17/J17) | L17: Customer submit + admin approve/reject advances self-drive bookings. Zoho webhook creates a KYC case. Uploads do not issue signed Cloudinary slots. Aadhaar hashing, DL expiry rules, and 12-month reuse are not built.
A18: 14 | B18: 10 Agreement & eSign | C18: document | D18: P0 | E18: Under Review | F18: =COUNTIF('10 Agreement & eSign'!F:F,"Done") | G18: =COUNTIF('10 Agreement & eSign'!F:F,"In Progress") | H18: =COUNTIF('10 Agreement & eSign'!F:F,"Under Review") | I18: =COUNTIF('10 Agreement & eSign'!F:F,"Not Started") | J18: =F18+G18+H18+I18 | K18: =IF(J18=0,0,F18/J18) | L18: HTML template render + send envelope (mock without LEEGALITY_API_KEY) + webhook/manual mark-signed advances booking to CONFIRMED. Not a real PDF yet. Vendor integration needs staging review.
A19: 15 | B19: 11 Fleet | C19: fleet | D19: P0 | E19: In Progress | F19: =COUNTIF('11 Fleet'!F:F,"Done") | G19: =COUNTIF('11 Fleet'!F:F,"In Progress") | H19: =COUNTIF('11 Fleet'!F:F,"Under Review") | I19: =COUNTIF('11 Fleet'!F:F,"Not Started") | J19: =F19+G19+H19+I19 | K19: =IF(J19=0,0,F19/J19) | L19: Cities, branches, vehicles CRUD and expiry read are live. Vehicle documents (RC/insurance/PUC) have a table but no admin CRUD. Assignment does not yet block on insurance dates.
A20: 16 | B20: 12 Maintenance | C20: fleet | D20: P2 | E20: In Progress | F20: =COUNTIF('12 Maintenance'!F:F,"Done") | G20: =COUNTIF('12 Maintenance'!F:F,"In Progress") | H20: =COUNTIF('12 Maintenance'!F:F,"Under Review") | I20: =COUNTIF('12 Maintenance'!F:F,"Not Started") | J20: =F20+G20+H20+I20 | K20: =IF(J20=0,0,F20/J20) | L20: Creating a maintenance job writes an availability block so search will not sell that car. Complete-job, parts, workshop CRUD, and admin UI are not built. After-MVP.
A21: 17 | B21: 13 Handover & Return | C21: fleet | D21: P1 | E21: In Progress | F21: =COUNTIF('13 Handover & Return'!F:F,"Done") | G21: =COUNTIF('13 Handover & Return'!F:F,"In Progress") | H21: =COUNTIF('13 Handover & Return'!F:F,"Under Review") | I21: =COUNTIF('13 Handover & Return'!F:F,"Not Started") | J21: =F21+G21+H21+I21 | K21: =IF(J21=0,0,F21/J21) | L21: Minimal handover/return APIs store odometer, fuel, photos, damages and move booking ONGOING → COMPLETED. Vehicle returns to drop branch and partner ledger is posted. Deposit auto-release and full damage matrix are not done. Delivery-exec app is out of scope.
A22: 18 | B22: 14 Drivers | C22: fleet | D22: P1 | E22: In Progress | F22: =COUNTIF('14 Drivers'!F:F,"Done") | G22: =COUNTIF('14 Drivers'!F:F,"In Progress") | H22: =COUNTIF('14 Drivers'!F:F,"Under Review") | I22: =COUNTIF('14 Drivers'!F:F,"Not Started") | J22: =F22+G22+H22+I22 | K22: =IF(J22=0,0,F22/J22) | L22: Driver CRUD + assign-to-booking work. Leave, availability calendar, DL validity, and single-assignment rules are not enforced. No driver marketplace (by design).
A23: 19 | B23: 15 Partners | C23: partner | D23: P2 | E23: In Progress | F23: =COUNTIF('15 Partners'!F:F,"Done") | G23: =COUNTIF('15 Partners'!F:F,"In Progress") | H23: =COUNTIF('15 Partners'!F:F,"Under Review") | I23: =COUNTIF('15 Partners'!F:F,"Not Started") | J23: =F23+G23+H23+I23 | K23: =IF(J23=0,0,F23/J23) | L23: Admin-only partner CRUD, commission rules, ledger on trip complete, settlement generate + mark-paid. No partner portal (confirmed exclusion). Open-damage hold and frozen-at-booking commission version still missing.
A24: 20 | B24: 16 Admin & Multi-city | C24: fleet + platform + apps/admin | D24: P0–P1 | E24: In Progress | F24: =COUNTIF('16 Admin & Multi-city'!F:F,"Done") | G24: =COUNTIF('16 Admin & Multi-city'!F:F,"In Progress") | H24: =COUNTIF('16 Admin & Multi-city'!F:F,"Under Review") | I24: =COUNTIF('16 Admin & Multi-city'!F:F,"Not Started") | J24: =F24+G24+H24+I24 | K24: =IF(J24=0,0,F24/J24) | L24: New ops console (port 3001) has dashboard, bookings, cars, vehicles, drivers, KYC, customers, payments, partners, leads, offers, CMS, reports. City/Branch exist on entities. StaffScope table exists but there is no assign-scope API or query filtering. Old admin UI still lives inside apps/web /admin.
A25: 21 | B25: 17 Finance & Reports | C25: platform + payment | D25: P2 | E25: In Progress | F25: =COUNTIF('17 Finance & Reports'!F:F,"Done") | G25: =COUNTIF('17 Finance & Reports'!F:F,"In Progress") | H25: =COUNTIF('17 Finance & Reports'!F:F,"Under Review") | I25: =COUNTIF('17 Finance & Reports'!F:F,"Not Started") | J25: =F25+G25+H25+I25 | K25: =IF(J25=0,0,F25/J25) | L25: Basic revenue + GST report endpoints and an admin reports page. No CSV export, deposit/partner reports, or Razorpay recon queue. GST is a flat 18% on invoice create.
A26: 22 | B26: 18 Offers & Wallet | C26: platform + payment + booking | D26: P1–P2 | E26: In Progress | F26: =COUNTIF('18 Offers & Wallet'!F:F,"Done") | G26: =COUNTIF('18 Offers & Wallet'!F:F,"In Progress") | H26: =COUNTIF('18 Offers & Wallet'!F:F,"Under Review") | I26: =COUNTIF('18 Offers & Wallet'!F:F,"Not Started") | J26: =F26+G26+H26+I26 | K26: =IF(J26=0,0,F26/J26) | L26: Coupon apply on quote is real (window, max redemptions, one per user). Admin can create offers. Wallet/loyalty rows are created at signup but earn/redeem/referral are not. P1 = coupons; P2 = wallet/loyalty.
A27: 23 | B27: 19 Reviews & Support | C27: platform | D27: P2 | E27: In Progress | F27: =COUNTIF('19 Reviews & Support'!F:F,"Done") | G27: =COUNTIF('19 Reviews & Support'!F:F,"In Progress") | H27: =COUNTIF('19 Reviews & Support'!F:F,"Under Review") | I27: =COUNTIF('19 Reviews & Support'!F:F,"Not Started") | J27: =F27+G27+H27+I27 | K27: =IF(J27=0,0,F27/J27) | L27: Customers can create a review (unpublished) and a ticket. Admin can list both. No moderate/publish, public car reviews, ticket assign/SLA, or customer ticket UI.
A28: 24 | B28: 20 Notifications | C28: notification + worker | D28: P0 | E28: Under Review | F28: =COUNTIF('20 Notifications'!F:F,"Done") | G28: =COUNTIF('20 Notifications'!F:F,"In Progress") | H28: =COUNTIF('20 Notifications'!F:F,"Under Review") | I28: =COUNTIF('20 Notifications'!F:F,"Not Started") | J28: =F28+G28+H28+I28 | K28: =IF(J28=0,0,F28/J28) | L28: Internal notify + templates + logs + retry cron. Gmail OAuth/app-password when env is set; otherwise console mock. OTP and booking_confirmed are wired. SMS/WhatsApp later. Staging review once Gmail env is present.
A29: 25 | B29: 21 CRM & Leads | C29: platform | D29: P1 | E29: In Progress | F29: =COUNTIF('21 CRM & Leads'!F:F,"Done") | G29: =COUNTIF('21 CRM & Leads'!F:F,"In Progress") | H29: =COUNTIF('21 CRM & Leads'!F:F,"Under Review") | I29: =COUNTIF('21 CRM & Leads'!F:F,"Not Started") | J29: =F29+G29+H29+I29 | K29: =IF(J29=0,0,F29/J29) | L29: Contact and public lead APIs + admin pipeline (NEW→LOST) + notes. Convert-to-booking and 7-day dedupe are not built. Admin /leads page exists.
A30: 26 | B30: 22 Mobile | C30: apps/mobile | D30: P2 | E30: In Progress | F30: =COUNTIF('22 Mobile'!F:F,"Done") | G30: =COUNTIF('22 Mobile'!F:F,"In Progress") | H30: =COUNTIF('22 Mobile'!F:F,"Under Review") | I30: =COUNTIF('22 Mobile'!F:F,"Not Started") | J30: =F30+G30+H30+I30 | K30: =IF(J30=0,0,F30/J30) | L30: Expo package with a single-screen prototype: dev sign-in, public car list, my bookings. No OTP, checkout, Razorpay, KYC, tracking, tickets, or store build. Spec: do not invest until web checkout is stable.
B31: TOTAL | F31: =SUM(F5:F30) | G31: =SUM(G5:G30) | H31: =SUM(H5:H30) | I31: =SUM(I5:I30) | J31: =SUM(J5:J30) | K31: =IF(J31=0,0,F31/J31)
A33: Status rollup (all items)
A34: Status | B34: Count
A35: Done | B35: =F31
A36: In Progress | B36: =G31
A37: Under Review | B37: =H31
A38: Not Started | B38: =I31

Sheet 01 Auth & Security
A1: 01 — Auth & security baseline
A2: Service: identity (apps/api) | Priority: P0 | Overall status: In Progress
A3: Firebase + Postgres user sync, OTP, roles, and audit exist. OTP is in-memory (not Redis). Google login and last-super-admin lock are not built. Staff city/branch scope is stored but not fully enforced on every list.
A4: ID | B4: Functionality | C4: Actor | D4: Implementation (what exists today) | E4: Code / API | F4: Status | G4: Priority | H4: Gaps / next work
A5: 01.01 | B5: Firebase ID token verification | C5: Backend | D5: API verifies Firebase ID tokens with firebase-admin when FIREBASE_PROJECT_ID is set; otherwise token resolve returns null. | E5: apps/api/src/auth.middleware.ts → verifyFirebase | F5: Under Review | G5: P0 | H5: Needs staging check with live Firebase project keys.
A6: 01.02 | B6: Dev auth bypass (local) | C6: Backend | D6: Bearer dev:email upserts a user and is allowed unless DEV_AUTH_BYPASS=false. | E6: auth.middleware.ts resolveUser | F6: Done | G6: P0 | H6: Must stay off in production.
A7: 01.03 | B7: Auth sync into PostgreSQL | C7: Customer / Backend | D7: POST /v1/auth/sync upserts User + CustomerProfile + CUSTOMER role + empty wallet/loyalty. | E7: POST /v1/auth/sync · identity.service.ts upsertFromIdentity | F7: Done | G7: P0 | H7: Gateway leftover service is unused; monolith API does this itself.
A8: 01.04 | B8: Email OTP send | C8: Customer | D8: POST /v1/auth/otp/send issues a 5-min code (in-memory Map) and calls notification service. Dev returns devCode. | E8: POST /v1/auth/otp/send | F8: In Progress | G8: P0 | H8: Replace Map with Redis; production must not expose devCode.
A9: 01.05 | B9: Email OTP verify | C9: Customer | D9: POST /v1/auth/otp/verify checks in-memory store. | E9: POST /v1/auth/otp/verify | F9: In Progress | G9: P0 | H9: No session mint beyond Firebase; OTP is email-verify helper only.
A10: 01.06 | B10: OTP rate limit | C10: Backend | D10: 8 requests / 15 minutes per IP on /v1/auth/otp/send. | E10: auth.middleware.ts rateLimitOtp | F10: Done | G10: P0 | H10: Raise to documented 3/15 min if product wants stricter.
A11: 01.07 | B11: Current user profile | C11: Customer | D11: GET /v1/me and PATCH /v1/me (name, phone, address JSON). | E11: GET/PATCH /v1/me | F11: Done | G11: P0 | H11: Phone change does not re-trigger OTP yet.
A12: 01.08 | B12: FCM / device token register | C12: Mobile / Web | D12: POST /v1/me/devices stores DeviceToken. | E12: POST /v1/me/devices | F12: Done | G12: P2 | H12: Mobile app does not call this yet.
A13: 01.09 | B13: Admin user search | C13: Admin | D13: GET /v1/admin/users?q= for SUPPORT/SALES/CITY_MANAGER/SUPER_ADMIN. | E13: GET /v1/admin/users · admin /customers | F13: Done | G13: P0 | H13: No pagination beyond simple query.
A14: 01.10 | B14: Assign staff roles | C14: Admin | D14: PATCH /v1/admin/users/:id/roles (SUPER_ADMIN). | E14: PATCH /v1/admin/users/:id/roles | F14: Done | G14: P0 | H14: Last remaining SUPER_ADMIN cannot be removed — not coded.
A15: 01.11 | B15: Disable user | C15: Admin | D15: POST /v1/admin/users/:id/disable. | E15: POST /v1/admin/users/:id/disable | F15: Done | G15: P0
A16: 01.12 | B16: Audit log | C16: Admin | D16: GET /v1/admin/audit. Writes happen on auth.sync, role change, disable, offline payment. | E16: GET /v1/admin/audit · AuditLog model | F16: In Progress | G16: P0 | H16: Not every privileged write is audited (refunds, KYC decision, status moves).
A17: 01.13 | B17: RBAC helpers | C17: Backend | D17: requireRoles / requireStaff / assertInternal / assertOwnerOrStaff. SUPER_ADMIN bypasses role checks. | E17: apps/api/src/lib/auth.ts | F17: Done | G17: P0 | H17: StaffScope (city/branch) is not applied as a query filter.
A18: 01.14 | B18: Public vs authed routes | C18: Backend | D18: Public: /v1/public/*, OTP, webhooks. Other /v1 requires Bearer. | E18: auth.middleware.ts PUBLIC | F18: Done | G18: P0 | H18: Internal routes live at /internal/* (not /v1/internal).
A19: 01.15 | B19: Web login | C19: Customer | D19: New login page uses Firebase/dev token via AuthContext. | E19: apps/web/src/ms/pages/Login.jsx · AuthContext.jsx | F19: In Progress | G19: P0 | H19: Google social login not started.
A20: 01.16 | B20: Admin login | C20: Admin | D20: apps/admin login stores dd_token and calls API. | E20: apps/admin/app/login/page.jsx | F20: In Progress | G20: P0 | H20: Uses same Bearer scheme; polish UX later.
A21: 01.17 | B21: Google / social login | C21: Customer | D21: Documented as later; no provider wiring. | E21: docs/modules/01-auth-security.md | F21: Not Started | G21: P2 | H21: Add Firebase Google provider after email path is stable.
A23: Counts | B23: Done | C23: In Progress | D23: Under Review | E23: Not Started
B24: =COUNTIF(F5:F21,"Done") | C24: =COUNTIF(F5:F21,"In Progress") | D24: =COUNTIF(F5:F21,"Under Review") | E24: =COUNTIF(F5:F21,"Not Started")

Sheet 02 Public CMS
A1: 02 — Public website & CMS
A2: Service: platform + apps/web | Priority: P1 | Overall status: In Progress
A3: Ported marketing site still runs in Next.js (home, blogs, monsoon bar). New CMS APIs exist for pages, banners, blogs, contact. Admin CMS page is a first version. Testimonials/comments still largely on the old UI.
A4: ID | B4: Functionality | C4: Actor | D4: Implementation (what exists today) | E4: Code / API | F4: Status | G4: Priority | H4: Gaps / next work
A5: 02.01 | B5: Marketing home | C5: Customer | D5: Ported Home + hero + why-us + fleet teaser + monsoon promo bar (still hardcoded CSS/content). | E5: apps/web/src/components/home/Home.jsx · MonsoonPromoBar.jsx | F5: In Progress | G5: P1 | H5: Drive strips/banners from GET /v1/public/banners.
A6: 02.02 | B6: Public CMS pages | C6: Customer | D6: GET /v1/public/pages/:slug returns published CmsPage. | E6: GET /v1/public/pages/:slug | F6: Done | G6: P1 | H6: Web legal pages still static TermsAndConditions, not CMS-driven.
A7: 02.03 | B7: Public banners | C7: Customer | D7: GET /v1/public/banners respects active + date window. | E7: GET /v1/public/banners | F7: Done | G7: P1 | H7: Home does not consume this API yet.
A8: 02.04 | B8: Public blogs list/detail | C8: Customer | D8: GET /v1/public/blogs and /:slug. Old AllBlogs/Blogspage UI still present. | E8: GET /v1/public/blogs · apps/web blogs components | F8: In Progress | G8: P1 | H8: Point web blogs at platform API instead of Firestore context.
A9: 02.05 | B9: Contact form → CRM lead | C9: Customer | D9: POST /v1/public/contact creates Lead + optional activity note. | E9: POST /v1/public/contact | F9: Done | G9: P1 | H9: Old Contact.jsx may still write the previous backend — switch to API.
A10: 02.06 | B10: Admin CMS pages | C10: Admin | D10: GET/POST /v1/admin/cms upsert by slug. Admin /cms page exists. | E10: CRUD /v1/admin/cms · apps/admin/app/cms/page.jsx | F10: In Progress | G10: P1 | H10: No unpublish workflow beyond published flag; no media picker.
A11: 02.07 | B11: Admin banners | C11: Admin | D11: GET/POST/PATCH /v1/admin/banners. | E11: /v1/admin/banners | F11: In Progress | G11: P1 | H11: No delete endpoint; admin UI may be combined into CMS page.
A12: 02.08 | B12: Testimonials | C12: Customer / Admin | D12: Testimonial model in Prisma. Live UI uses old TestimonialContext (ported site). | E12: schema Testimonial · apps/web Testimonial.jsx | F12: Not Started | G12: P1 | H12: Add public + admin APIs and wire home.
A13: 02.09 | B13: Blog comments | C13: Customer | D13: BlogComment on schema; public blog include comments. No POST comment API. | E13: schema BlogComment | F13: Not Started | G13: P2 | H13: Auth or moderation flag per spec.
A14: 02.10 | B14: SEO / page metadata | C14: Admin | D14: PageMetadata model. Web has SeoDefaults.jsx on old site. | E14: schema PageMetadata · SeoDefaults.jsx | F14: In Progress | G14: P1 | H14: Admin metadata CRUD not on new API.
A15: 02.11 | B15: WhatsApp / enquiry CTAs | C15: Customer | D15: Ported WhatsAppPopup + ContactPopup + Numberattach. | E15: apps/web WhatsAppPopup · ContactPopup | F15: In Progress | G15: P1 | H15: Clicks are not logged as CRM leads yet.
A17: Counts | B17: Done | C17: In Progress | D17: Under Review | E17: Not Started
B18: =COUNTIF(F5:F15,"Done") | C18: =COUNTIF(F5:F15,"In Progress") | D18: =COUNTIF(F5:F15,"Under Review") | E18: =COUNTIF(F5:F15,"Not Started")

Sheet 03 Customer Dashboard
A1: 03 — Customer accounts & web dashboard
A2: Service: identity + booking + payment + document + web | Priority: P0 | Overall status: In Progress
A3: Logged-in /account lists bookings and KYC status. APIs exist for invoices, wallet, tickets, agreements-by-id. Dedicated screens for invoices/wallet/tickets/agreements are not built yet.
A4: ID | B4: Functionality | C4: Actor | D4: Implementation (what exists today) | E4: Code / API | F4: Status | G4: Priority | H4: Gaps / next work
A5: 03.01 | B5: Account home | C5: Customer | D5: /account shows name, KYC status, booking list with track links. | E5: apps/web/src/ms/pages/Account.jsx · GET /v1/me/bookings | F5: In Progress | G5: P0 | H5: No profile edit form, addresses UI, or invoices/wallet/tickets links.
A6: 03.02 | B6: My bookings | C6: Customer | D6: GET /v1/me/bookings returns history + payments. | E6: GET /v1/me/bookings | F6: Done | G6: P0 | H6: No /account/bookings/[id] detail page (uses /track/:id).
A7: 03.03 | B7: KYC from account | C7: Customer | D7: /account/kyc page + GET /v1/me/kyc. | E7: Kyc.jsx · GET /v1/me/kyc | F7: In Progress | G7: P0 | H7: See module 09 for upload/signed-URL gaps.
A8: 03.04 | B8: Invoices download | C8: Customer | D8: GET /v1/me/invoices returns Invoice + lines. No account invoices screen. | E8: GET /v1/me/invoices | F8: In Progress | G8: P0 | H8: Build /account/invoices and PDF download.
A9: 03.05 | B9: Wallet view | C9: Customer | D9: GET /v1/me/wallet upserts Wallet and returns txns. No UI. | E9: GET /v1/me/wallet | F9: In Progress | G9: P2 | H9: No credit/debit at checkout (module 18).
A10: 03.06 | B10: Support tickets | C10: Customer | D10: POST /v1/tickets creates ticket + first message. No /account/tickets UI. | E10: POST /v1/tickets | F10: In Progress | G10: P2 | H10: No customer reply thread API beyond create.
A11: 03.07 | B11: Agreements list/download | C11: Customer | D11: GET /v1/me/agreements/:id by id only — no list endpoint or page. | E11: GET /v1/me/agreements/:id | F11: Not Started | G11: P0 | H11: Add GET /v1/me/agreements and /account/agreements.
A12: 03.08 | B12: No impersonation | C12: Admin | D12: No impersonate API (support is read-only by design). | E12: docs/modules/03-customer-dashboard.md | F12: Done | G12: P0 | H12: Keep it this way.
A14: Counts | B14: Done | C14: In Progress | D14: Under Review | E14: Not Started
B15: =COUNTIF(F5:F12,"Done") | C15: =COUNTIF(F5:F12,"In Progress") | D15: =COUNTIF(F5:F12,"Under Review") | E15: =COUNTIF(F5:F12,"Not Started")

Sheet 04 Search & Availability
A1: 04 — Search, discovery & availability
A2: Service: catalog | Priority: P0 | Overall status: In Progress
A3: Public search, car detail, availability, pricing CRUD, HOLD reserve/release/confirm, and the worker HOLD sweeper are implemented. Search UI is /fleet. Seasonal pricing and a hard DB lock against double-book are still open.
A4: ID | B4: Functionality | C4: Actor | D4: Implementation (what exists today) | E4: Code / API | F4: Status | G4: Priority | H4: Gaps / next work
A5: 04.01 | B5: Public search | C5: Customer | D5: GET /v1/public/search filters city, seats, fuel, transmission, price, rentalType; returns from-price + available flag. | E5: GET /v1/public/search · catalog.service.ts search | F5: Done | G5: P0 | H5: No popularity sort; unpublished models excluded.
A6: 04.02 | B6: Car detail by slug | C6: Customer | D6: GET /v1/public/cars/:slug with images, pricing, city. | E6: GET /v1/public/cars/:slug · CarDetail.jsx | F6: Done | G6: P0 | H6: Calendar of blocked dates is thin.
A7: 04.03 | B7: Availability check | C7: Customer | D7: GET /v1/public/cars/:id/availability uses buffer hours and free-vehicle search. | E7: GET /v1/public/cars/:id/availability | F7: Done | G7: P0
A8: 04.04 | B8: Overlap + buffer + maintenance | C8: Backend | D8: vehicleBusy checks blocking booking statuses, AvailabilityBlock, MaintenanceJob. Buffer default 3h (BUFFER_HOURS). | E8: catalog.service.ts vehicleBusy · findFreeVehicle | F8: Done | G8: P0 | H8: No SELECT FOR UPDATE / serializable tx — race possible under concurrent checkout.
A9: 04.05 | B9: HOLD reserve / release / confirm | C9: Backend | D9: Internal reserve creates HOLD:bookingId block; confirm renames to BOOKING:; release deletes. | E9: POST /internal/availability/reserve|release|confirm | F9: Done | G9: P0 | H9: Requires x-internal-token.
A10: 04.06 | B10: HOLD sweeper | C10: System | D10: Worker cron every minute expires unpaid HOLD/AWAITING_PAYMENT and releases availability. | E10: apps/worker hold-sweeper.job.ts · POST /internal/holds/expire | F10: Done | G10: P0 | H10: HOLD_MINUTES env (default 15).
A11: 04.07 | B11: Admin car models CRUD | C11: Admin | D11: GET/POST/PATCH/DELETE /v1/admin/car-models. Admin /cars page. | E11: /v1/admin/car-models · apps/admin/app/cars | F11: In Progress | G11: P0 | H11: Image management is create-time only.
A12: 04.08 | B12: Pricing rules CRUD | C12: Admin | D12: GET/POST/PUT/DELETE /v1/admin/pricing-rules (daily/hourly/extraKm/deposit). | E12: /v1/admin/pricing-rules | F12: Done | G12: P0 | H12: No seasonal / date-window rules.
A13: 04.09 | B13: Web search UI | C13: Customer | D13: /fleet uses new Search.jsx against the API (old /cars carousel still ported). | E13: apps/web/src/ms/pages/Search.jsx | F13: In Progress | G13: P0 | H13: Unify /cars vs /fleet; add sort chips.
A14: 04.10 | B14: Seasonal / featured pricing | C14: Admin | D14: featured + displayOrder on CarModel only. | E14: CarModel.featured | F14: Not Started | G14: P1 | H14: Add date-ranged PricingRule.
A16: Counts | B16: Done | C16: In Progress | D16: Under Review | E16: Not Started
B17: =COUNTIF(F5:F14,"Done") | C17: =COUNTIF(F5:F14,"In Progress") | D17: =COUNTIF(F5:F14,"Under Review") | E17: =COUNTIF(F5:F14,"Not Started")

Sheet 05 Booking Engine
A1: 05 — Booking engine (all rental types)
A2: Service: booking | Priority: P0 | Overall status: In Progress
A3: Quote → HOLD → pay → KYC → signature → CONFIRMED path is coded, with admin assign vehicle/driver and cancel. Self-drive vs with-driver branch after payment. Chauffeur product rules, policy-based cancel, and admin-created bookings are incomplete.
A4: ID | B4: Functionality | C4: Actor | D4: Implementation (what exists today) | E4: Code / API | F4: Status | G4: Priority | H4: Gaps / next work
A5: 05.01 | B5: Create quote (price freeze) | C5: Customer | D5: POST /v1/quotes computes days/hours from PricingRule, optional offer, TTL ~20 min. | E5: POST /v1/quotes · booking.service.ts quote | F5: Done | G5: P0 | H5: Airport wait/night/one-way extras not auto-added (see module 08).
A6: 05.02 | B6: Apply offer on quote | C6: Customer | D6: POST /v1/quotes/:id/apply-offer validates window, cap, per-user. | E6: POST /v1/quotes/:id/apply-offer | F6: Done | G6: P1 | H6: No floor-price guard.
A7: 05.03 | B7: Create booking from quote | C7: Customer | D7: POST /v1/bookings creates HOLD, reserves vehicle, moves to AWAITING_PAYMENT or cancels if no car. | E7: POST /v1/bookings | F7: Done | G7: P0 | H7: Quote TTL vs HOLD sweeper both apply.
A8: 05.04 | B8: Get booking + history | C8: Customer / Admin | D8: GET /v1/bookings/:id includes history, extras, payments, KYC, agreements, driver, inspections. Owner or staff. | E8: GET /v1/bookings/:id | F8: Done | G8: P0
A9: 05.05 | B9: Cancel booking | C9: Customer / Admin | D9: Allowed until HANDOVER/ONGOING/COMPLETED. Releases availability. | E9: POST /v1/bookings/:id/cancel | F9: In Progress | G9: P0 | H9: No hours-before-start policy or auto refund.
A10: 05.06 | B10: Lifecycle after payment | C10: Backend | D10: TOKEN/BALANCE success → SELF_DRIVE AWAITING_KYC else CONFIRMED. KYC approved → AWAITING_SIGNATURE. Signed → CONFIRMED. | E10: internal /payment-captured /kyc-approved /agreement-signed | F10: Done | G10: P0 | H10: With-driver skips KYC/sign by design.
A11: 05.07 | B11: Admin bookings list / patch / status | C11: Admin | D11: GET /v1/admin/bookings, PATCH notes/dates/flight, POST status with confirm/release side effects. | E11: /v1/admin/bookings* · apps/admin/app/bookings | F11: In Progress | G11: P0 | H11: Date change does not re-quote or re-check availability.
A12: 05.08 | B12: Assign vehicle | C12: Admin | D12: POST /v1/admin/bookings/:id/assign-vehicle. | E12: POST .../assign-vehicle | F12: In Progress | G12: P0 | H12: Does not re-validate insurance/status/overlap.
A13: 05.09 | B13: Assign driver | C13: Admin | D13: POST assign-driver upserts DriverAssignment. | E13: POST .../assign-driver | F13: In Progress | G13: P1 | H13: No one-ongoing-trip or city-match validation.
A14: 05.10 | B14: Status history | C14: Backend | D14: BookingStatusHistory written on create, pay, KYC, sign, cancel, expire, handover, return. | E14: BookingStatusHistory | F14: Done | G14: P0
A15: 05.11 | B15: Web checkout | C15: Customer | D15: /checkout/:quoteId applies offer, creates booking, mock-verifies Razorpay, goes to success. | E15: Checkout.jsx | F15: In Progress | G15: P0 | H15: No live Razorpay.js checkout when mock=false.
A16: 05.12 | B16: Tracking page | C16: Customer | D16: /track/:bookingId new Track.jsx (old /order-tracking still exists). | E16: Track.jsx | F16: In Progress | G16: P0 | H16: Logged-out track-by-phone OTP not built.
A17: 05.13 | B17: Realtime status | C17: Customer | D17: apps/socket BookingGateway on :4010. | E17: apps/socket | F17: In Progress | G17: P1 | H17: Web/admin do not subscribe yet.
A18: 05.14 | B18: Admin create booking on behalf | C18: Admin | D18: No dedicated sales-create endpoint; would use customer quote APIs. | E18: — | F18: Not Started | G18: P1 | H18: Add POST /v1/admin/bookings with userId.
A19: 05.15 | B19: NO_SHOW / grace | C19: Admin | D19: Status enum includes NO_SHOW; admin can POST status. No automatic grace job. | E19: BookingStatus.NO_SHOW | F19: Not Started | G19: P1 | H19: Add sweeper after start time.
A21: Counts | B21: Done | C21: In Progress | D21: Under Review | E21: Not Started
B22: =COUNTIF(F5:F19,"Done") | C22: =COUNTIF(F5:F19,"In Progress") | D22: =COUNTIF(F5:F19,"Under Review") | E22: =COUNTIF(F5:F19,"Not Started")

Sheet 06 Payments
A1: 06 — Payments, invoices & deposits
A2: Service: payment | Priority: P0 | Overall status: Under Review
A3: Razorpay order + verify + webhook + mock mode, invoices with flat 18% GST, offline pay, refund rows, deposit flags. Live Razorpay, real refunds, state-wise GST, and deposit authorize/capture need review in staging.
A4: ID | B4: Functionality | C4: Actor | D4: Implementation (what exists today) | E4: Code / API | F4: Status | G4: Priority | H4: Gaps / next work
A5: 06.01 | B5: Create payment order (token/balance/deposit) | C5: Customer | D5: POST /v1/payments/orders uses booking amount. Mock order if no RAZORPAY_KEY_ID or PAYMENTS_MOCK=true. | E5: POST /v1/payments/orders | F5: Done | G5: P0 | H5: Amount is booking.amountPaise even for BALANCE (not remaining due).
A6: 06.02 | B6: Client verify | C6: Customer | D6: POST /v1/payments/verify HMAC of order|payment; mock marks SUCCESS. | E6: POST /v1/payments/verify | F6: Done | G6: P0 | H6: Webhook should remain source of truth in prod.
A7: 06.03 | B7: Razorpay webhook | C7: System | D7: POST /v1/webhooks/razorpay signature check + idempotent eventId on captured/authorized. | E7: POST /v1/webhooks/razorpay | F7: Under Review | G7: P0 | H7: Test with Razorpay test-mode webhook secret.
A8: 06.04 | B8: Invoice on success | C8: Customer | D8: Creates INV-YEAR-##### with GST 18% lines after SUCCESS. | E8: payment.service.ts afterSuccess | F8: In Progress | G8: P1 | H8: Not CGST/SGST vs IGST by state; no PDF.
A9: 06.05 | B9: List my invoices | C9: Customer | D9: GET /v1/me/invoices. | E9: GET /v1/me/invoices | F9: Done | G9: P0 | H9: No customer UI yet.
A10: 06.06 | B10: Offline cash/UPI | C10: Admin | D10: POST /v1/admin/payments/offline marks SUCCESS and runs afterSuccess + audit. | E10: POST /v1/admin/payments/offline | F10: Done | G10: P1 | H10: No branch-scoping of who can record.
A11: 06.07 | B11: Refunds | C11: Admin | D11: POST /v1/admin/payments/:id/refund writes Refund row and payment status. Does not call Razorpay refund API. | E11: POST /v1/admin/payments/:id/refund | F11: In Progress | G11: P1 | H11: Wire Razorpay refunds + webhook.
A12: 06.08 | B12: Security deposit capture/release | C12: Admin | D12: POST deposits/:id/capture|release toggles held/released flags. | E12: POST /v1/admin/deposits/:id/* | F12: In Progress | G12: P1 | H12: No Razorpay authorize; no auto-release after return inspection.
A13: 06.09 | B13: Wallet read | C13: Customer | D13: GET /v1/me/wallet. | E13: GET /v1/me/wallet | F13: In Progress | G13: P2 | H13: Cannot pay token from wallet.
A14: 06.10 | B14: Admin payments UI | C14: Admin | D14: apps/admin/app/payments page. | E14: apps/admin/app/payments/page.jsx | F14: In Progress | G14: P0 | H14: Needs refund/deposit actions in UI.
A15: 06.11 | B15: Razorpay settlement recon | C15: Admin | D15: No PayoutReconciliation flow. | E15: — | F15: Not Started | G15: P2 | H15: Finance mismatch queue.
A17: Counts | B17: Done | C17: In Progress | D17: Under Review | E17: Not Started
B18: =COUNTIF(F5:F15,"Done") | C18: =COUNTIF(F5:F15,"In Progress") | D18: =COUNTIF(F5:F15,"Under Review") | E18: =COUNTIF(F5:F15,"Not Started")

Sheet 07 Subscription
A1: 07 — Car subscription & long-term
A2: Service: booking + catalog | Priority: P2 | Overall status: In Progress
A3: Data model + POST /v1/subscriptions creates a SUBSCRIPTION booking from a plan. No public plans API, swap, pause, or recurring invoices. After-MVP.
A4: ID | B4: Functionality | C4: Actor | D4: Implementation (what exists today) | E4: Code / API | F4: Status | G4: Priority | H4: Gaps / next work
A5: 07.01 | B5: Subscription plan table | C5: Backend | D5: SubscriptionPlan (months, price, carModel) in Prisma. | E5: packages/database/prisma/schema.prisma SubscriptionPlan | F5: Done | G5: P2 | H5: No admin CRUD API for plans.
A6: 07.02 | B6: Start subscription | C6: Customer | D6: POST /v1/subscriptions quotes SUBSCRIPTION, overwrites amount to plan price, creates booking + Subscription row. | E6: POST /v1/subscriptions | F6: In Progress | G6: P2 | H6: Starts immediately; no handover-aligned start; needs available vehicle.
A7: 07.03 | B7: Public plans listing | C7: Customer | D7: GET /v1/public/subscriptions/plans not implemented. | E7: — | F7: Not Started | G7: P2
A8: 07.04 | B8: Swap / early close | C8: Admin | D8: POST /v1/admin/subscriptions/:id/swap|close not implemented. | E8: — | F8: Not Started | G8: P2
A9: 07.05 | B9: Monthly invoice / mandate | C9: Finance | D9: Spec says invoice-per-month; not built. | E9: — | F9: Not Started | G9: P2 | H9: Razorpay mandate later.
A11: Counts | B11: Done | C11: In Progress | D11: Under Review | E11: Not Started
B12: =COUNTIF(F5:F9,"Done") | C12: =COUNTIF(F5:F9,"In Progress") | D12: =COUNTIF(F5:F9,"Under Review") | E12: =COUNTIF(F5:F9,"Not Started")

Sheet 08 Airport & Packages
A1: 08 — Airport, outstation, one-way & tours
A2: Service: booking | Priority: P1–P2 | Overall status: In Progress
A3: Tour packages and city-pair one-way rates have APIs. Quote accepts all RentalType values but pricing is still daily/hourly rules only — no terminal wait slabs, night charges, or driver allowance.
A4: ID | B4: Functionality | C4: Actor | D4: Implementation (what exists today) | E4: Code / API | F4: Status | G4: Priority | H4: Gaps / next work
A5: 08.01 | B5: Public tour packages | C5: Customer | D5: GET /v1/public/packages published TourPackage + TourDay. | E5: GET /v1/public/packages | F5: Done | G5: P2 | H5: No /packages web route.
A6: 08.02 | B6: Admin packages CRUD | C6: Admin | D6: GET/POST/PATCH + POST delete /v1/admin/packages. | E6: /v1/admin/packages | F6: In Progress | G6: P2 | H6: No admin UI page; daysDetail not edited on create.
A7: 08.03 | B7: City-pair one-way fee | C7: Admin | D7: GET/POST /v1/admin/city-pairs upserts CityPairRate. | E7: /v1/admin/city-pairs | F7: In Progress | G7: P1 | H7: Quote engine does not add oneWayPaise yet.
A8: 08.04 | B8: Quote product types | C8: Customer | D8: POST /v1/quotes accepts SELF_DRIVE, WITH_DRIVER_*, AIRPORT, OUTSTATION, ONE_WAY, TOUR, SUBSCRIPTION via Prisma enum. | E8: POST /v1/quotes rentalType | F8: In Progress | G8: P1 | H8: WITH_DRIVER_LOCAL uses hourlyPaise; others use dailyPaise only.
A9: 08.05 | B9: Flight number | C9: Admin | D9: adminPatch can set flightNumber. | E9: PATCH /v1/admin/bookings/:id | F9: In Progress | G9: P1 | H9: Customer checkout does not collect flight/terminal.
A10: 08.06 | B10: Airport terminals & wait slabs | C10: Admin | D10: AirportTerminal model only — no API. | E10: schema AirportTerminal | F10: Not Started | G10: P1 | H10: Free wait minutes + night charges.
A11: 08.07 | B11: Outstation driver allowance | C11: Backend | D11: Not in quote calculation. | E11: — | F11: Not Started | G11: P1 | H11: Auto-add per night.
A12: 08.08 | B12: Web packages page | C12: Customer | D12: Not in Container.jsx routes. | E12: — | F12: Not Started | G12: P2 | H12: Add /packages.
A14: Counts | B14: Done | C14: In Progress | D14: Under Review | E14: Not Started
B15: =COUNTIF(F5:F12,"Done") | C15: =COUNTIF(F5:F12,"In Progress") | D15: =COUNTIF(F5:F12,"Under Review") | E15: =COUNTIF(F5:F12,"Not Started")

Sheet 09 KYC & Documents
A1: 09 — Legal KYC & documents
A2: Service: document | Priority: P0 | Overall status: In Progress
A3: Customer submit + admin approve/reject advances self-drive bookings. Zoho webhook creates a KYC case. Uploads do not issue signed Cloudinary slots. Aadhaar hashing, DL expiry rules, and 12-month reuse are not built.
A4: ID | B4: Functionality | C4: Actor | D4: Implementation (what exists today) | E4: Code / API | F4: Status | G4: Priority | H4: Gaps / next work
A5: 09.01 | B5: Submit KYC case | C5: Customer | D5: POST /v1/kyc/submit creates KycCase SUBMITTED + KycDocument URLs; sets profile.kycStatus. | E5: POST /v1/kyc/submit | F5: Done | G5: P0 | H5: No MIME/size validation server-side.
